Workbook

Sheet Inicio
B6: Razón Social:
B8: NIF:
B10: PERIODO DE REFERENCIA | D10: fecha inicio | F10: fecha fin
B16: TABLAS DEL REGISTRO RETRIBUTIVO
B22: TABLAS ADICIONALES PARA EMPRESAS QUE REALICEN AUDITORÍA RETRIBUTIVA (TRABAJOS DE IGUAL VALOR)

Sheet CAMPOS
D3: CAMPO | E3: Tipo | F3: Reg. | G3: Descripción | H3: Formato | I3: Valores permitidos
F4: Ret.
D5: id | E5: PERSONA | F5: x | G5: Identificador único para cada persona trabajadora. | H5: Número entero
D6: Sexo | E6: PERSONA | F6: x | G6: Sexo de la persona trabajadora. | H6: Texto | I6: Hombre / Mujer
D7: Fecha Nacimiento | E7: PERSONA | G7: Fecha de nacimiento de la persona trabajadora. | H7: Fecha | I7: dd-mm-aa
D8: Nivel de Estudios | E8: PERSONA | G8: Nivel académico actual de la persona trabajadora. | H8: Texto
D9: Situación Familiar | E9: PERSONA | G9: Situación familiar conforme a MODELO 145 AEAT. | H9: Número entero | I9: conforme a MODELO 145 AEAT
D10: Hijos/as | E10: PERSONA | G10: Número de hijos/as de la persona trabajadora, conforme a MODELO 145 AEAT. | H10: Número entero
D11: Fecha de Contratación | E11: SITUACION CONTRACTUAL | F11: x | G11: Fecha de contratación. Se emplea exclusivamente en el caso de contrataciones con fecha posterior al inicio del periodo de referencia. Si es anterior, puede dejarse en blanco. 1/1/1900 = 0. | H11: Fecha | I11: dd-mm-aa
D12: Fecha fin contrato | E12: SITUACION CONTRACTUAL | F12: x | G12: Fecha de fin del contrato. Se emplea exclusivamente en el caso de contrataciones finalizadas antes del fin del periodo de referencia. Si es posterior, puede dejarse en blanco. 1/1/1900 = 0. | H12: Fecha | I12: dd-mm-aa
D13: Fecha de Antigüedad | E13: SITUACION CONTRACTUAL | G13: Fecha que aplica a efectos de cálculo de antigüedad (puede o no coincidir con la fecha de contratación). | H13: Fecha | I13: dd-mm-aa
D14: Fecha Inicio Sit. Contract. | E14: SITUACION CONTRACTUAL | F14: x | G14: Fecha de inicio de la Situación contractual. Se emplea exclusivamente en el caso de inicio de Situación contractual con fecha posterior al inicio del periodo de referencia. Si es anterior, puede dejarse en blanco. 1/1/1900 = 0. | H14: Fecha | I14: dd-mm-aa
D15: Fecha Fin Sit. Contract. | E15: SITUACION CONTRACTUAL | F15: x | G15: Fecha de fin de la Situación contractual. Se emplea exclusivamente en el caso de fin de Situación contractual con fecha anterior al fin del periodo de referencia. Si es anterior, puede dejarse en blanco. 1/1/1900 = 0. | H15: Fecha | I15: dd-mm-aa
D16: % de jornada | E16: SITUACION CONTRACTUAL | F16: x | G16: % de jornada realizada por la persona en el periodo de referencia y Situación contractual, considerando 100% como jornada completa, y sin considerar las reducciones de jornada. Si el % ha variado a lo largo del periodo de referencia, deberá asegurarse que para el periodo indicado (inicio y fin de contrato que se indique), el % de jornada sea constante, y que los importes de retribución son igualmente consistentes con ese %. | H16: Porcentaje | I16: %
D17: % jornada reducida | E17: SITUACION CONTRACTUAL | F17: x | G17: Medido en relación a la jornada por contrato en la Situación contractual. Ejemplo: si una persona con contrato a tiempo completo reduce 1/3 su jornada, el % a indicar será el 66,67%. Si una persona con contrato a tiempo parcial del 50% se reduce la jornada en 1/3, el % a indicar será también del 66,67%. Dejar en blanco si no hay reducción de jornada. | H17: Porcentaje | I17: %
D18: motivo reducción | E18: SITUACION CONTRACTUAL | G18: Motivo de Reducción de Jornada (dejar en blanco si no hay reducción de jornada) en la Situación contractual. | H18: Texto | I18: ver tabla "Motivo reducción de jornada"
D19: Clave de Contrato | E19: SITUACION CONTRACTUAL | G19: Clave del contrato actual de la persona trabajadora en la Situación contractual, de acuerdo a los códigos de la Seguridad Social. | H19: Número entero | I19: ver tabla "Clave de Contrato"
D20: Area-empresa | E20: PUESTO ACTUAL | G20: Área de la empresa en la que trabaja la persona en la Situación contractual. Si resulta útil, puede emplearse este campo y el siguiente para reflejar cualquier otra organización de la empresa (centro de trabajo, división, dirección territorial, etc.). | H20: Texto | I20: los de la empresa
D21: Dpto-empresa | E21: PUESTO ACTUAL | G21: Departamento actual de la persona trabajadora en la Situación contractual. | H21: Texto | I21: los de la empresa
D22: Puesto-empresa | E22: PUESTO ACTUAL | F22: x | G22: Puesto actual de la persona trabajadora en la Situación Contractual. Para una mejor visualización de los datos, se recomienda utilizar una nomenclatura con denominaciones breves. | H22: Texto | I22: los de la empresa
D23: Horario (continuo/ partido) | E23: PUESTO ACTUAL | G23: Indica el tipo de horario que realiza en la Situación Contractual. | H23: Texto | I23: continuo/partido
D24: Trabajo a turnos | E24: PUESTO ACTUAL | G24: Indica si realiza o no trabajo a turnos en la Situación Contractual. | H24: Texto | I24: Sí/No
D25: Escala-empresa | E25: PUESTO ACTUAL | G25: Escala actual de la persona trabajadora en la Situación Contractual, conforme a la escala de mando vigente en la empresa. | H25: Texto | I25: los de la empresa
D26: AGRUP. CLAS. PROF. | E26: PUESTO ACTUAL | F26: x | G26: Agrupación en la que queda agrupada la persona en su Situación Contractual según la clasificación profesional de la empresa de acuerdo con el Convenio de aplicación. Se nombrarán necesariamente como GRUPO 01, GRUPO 02, etc., hasta un máximo de 30. Se recomienda que este orden esté relacionado con la jerarquía dentro de las empresas. Esta agrupación es la que se emplea en las TABLAS DEL REGISTRO RETRIBUTIVO | H26: Texto | I26: GRUPO 01, GRUPO 02, … hasta GRUPO 30 (máximo)
D27: AGRUP. VALOR. PTO. | E27: PUESTO ACTUAL | F27: (x) | G27: Agrupación en la que queda agrupada la persona en su Situación Contractual según la valoración su puesto de trabajo (solamente para empresas con auditoría retributiva). Se nombrarán necesariamente como ESCALA 01, ESCALA 02, etc., hasta un máximo de 30. Se recomienda que este orden esté relacionado el valor de los puestos agrupados en esa ESCALA. Esta agrupación es la que se emplea en las TABLAS ADICIONALES PARA EMPRESAS QUE REALICEN AUDITORÍA RERIBUTIVA (TRABAJOS DE IGUAL VALOR) | H27: Texto | I27: ESCALA 01, ESCALA 02…, hasta ESCALA 30 (máximo)
D28: Convenio/Área | E28: CONTRATO-CONVENIO | F28: x | G28: Convenio de aplicación de cada contrato. No hace falta incluir el nº completo del convenio, basta una nomenclatura suficiente para identificarlo. En convenios con varias Áreas, indicar conjuntamente el Área para cada caso. | H28: Texto | I28: los del convenio y contrato
D29: Categoría profesional | E29: CONTRATO-CONVENIO | G29: Categoría profesional que corresponde a la persona en su Situación Contractual, conforme al Convenio. (Puede ser que el Convenio de referencia no utilice Categorías, sino Grupos, ver abajo). | H29: Texto | I29: los del convenio y contrato
D30: Grupo profesional | E30: CONTRATO-CONVENIO | G30: Grupo profesional que corresponde a la persona en su Situación Contractual, conforme al Convenio. | H30: Texto | I30: los del convenio y contrato
D31: Nivel | E31: CONTRATO-CONVENIO | F31: x | G31: Nivel (retributivo) que corresponde a la persona en su Situación Contractual, conforme al Convenio. | H31: Texto | I31: los del convenio y contrato
D32: Grupo de Cotización Seg.Social. | E32: SEG-SOCIAL | G32: Grupo de cotización de la Seguridad Social. | H32: Número entero | I32: ver aquí
D33: S.BASE | E33: RETRIBUCION | F33: x | G33: Salario base de la persona (sumatorio de importes correspondiente al periodo de referencia y Situación Contractual). Se deben añadir las pagas extraordinarias percibidas. | H33: Moneda
D34: Conc.Sal.01 | E34: RETRIBUCION | F34: x | G34: Concepto Salarial 01. A determinar por la organización (sumatorio de importes correspondiente al periodo de referencia y Situación Contractual). | H34: Moneda
D35: Conc.Sal.02 | E35: RETRIBUCION | F35: x | G35: Concepto Salarial 02. A determinar por la organización (sumatorio de importes correspondiente al periodo de referencia y Situación Contractual) | H35: Moneda
D36: Conc.Sal.03 | E36: RETRIBUCION | F36: x | G36: Concepto Salarial 03. A determinar por la organización (sumatorio de importes correspondiente al periodo de referencia y Situación Contractual). | H36: Moneda
D37: Conc.Sal.04 | E37: RETRIBUCION | F37: x | G37: Concepto Salarial 04. A determinar por la organización (sumatorio de importes correspondiente al periodo de referencia y Situación Contractual). | H37: Moneda
D38: Conc.Sal.05 | E38: RETRIBUCION | F38: x | G38: Concepto Salarial 05. A determinar por la organización (sumatorio de importes correspondiente al periodo de referencia y Situación Contractual).. | H38: Moneda
D39: … | E39: … | F39: … | G39: …
D40: Conc.Sal.30 | E40: RETRIBUCION | F40: x | G40: Concepto Salarial 30. A determinar por la organización (sumatorio de importes correspondiente al periodo de referencia y Situación Contractual). | H40: Moneda
D41: C.Extra.01 | E41: RETRIBUCION | F41: x | G41: Concepto Extrasalarial 01. A determinar por la organización (sumatorio de importes correspondiente al periodo de referencia y Situación Contractual). | H41: Moneda
D42: … | E42: … | F42: … | G42: … | H42: Moneda
...

Sheet CONC.RETR
B2: TABLA DE CONCEPTOS RETRIBUTIVOS
E4: Form. Retrib. | G4: Tipo de Retribución
E6: Retrib | G6: Nombre
E7: Dinero | G7: Salario Base
E8: En especie | G8: Comp. Salarial
G9: Extrasalarial
B11: Valor | C11: Nombre Corto | D11: Descripción | E11: Retrib | F11: Tipo | G11: Normalizable | H11: Anualizable | J11: AGRUP. CLAS. PROF. | L11: AGRUP. VALOR. PTO
B12: S.BASE | F12: Salario Base | J12: GRUPO 01 | L12: ESCALA 01
B13: Conc.Sal.01 | F13: Comp. Salarial | J13: GRUPO 02 | L13: ESCALA 02
B14: Conc.Sal.02 | F14: Comp. Salarial | J14: GRUPO 03 | L14: ESCALA 03
B15: Conc.Sal.03 | F15: Comp. Salarial | J15: GRUPO 04 | L15: ESCALA 04
B16: Conc.Sal.04 | F16: Comp. Salarial | J16: GRUPO 05 | L16: ESCALA 05
B17: Conc.Sal.05 | F17: Comp. Salarial | J17: GRUPO 06 | L17: ESCALA 06
B18: Conc.Sal.06 | F18: Comp. Salarial | J18: GRUPO 07 | L18: ESCALA 07
B19: Conc.Sal.07 | F19: Comp. Salarial | J19: GRUPO 08 | L19: ESCALA 08
B20: Conc.Sal.08 | F20: Comp. Salarial | J20: GRUPO 09 | L20: ESCALA 09
B21: Conc.Sal.09 | F21: Comp. Salarial | J21: GRUPO 10 | L21: ESCALA 10
B22: Conc.Sal.10 | F22: Comp. Salarial | J22: GRUPO 11 | L22: ESCALA 11
B23: Conc.Sal.11 | F23: Comp. Salarial | J23: GRUPO 12 | L23: ESCALA 12
... B41: Conc.Sal.29 | F41: Comp. Salarial | J41: GRUPO 30 | L41: ESCALA 30
B42: Conc.Sal.30 | F42: Comp. Salarial
B43: C.Extra.01 | F43: Extrasalarial
B44: C.Extra.02 | F44: Extrasalarial
B45: C.Extra.03 | F45: Extrasalarial
B46: C.Extra.04 | F46: Extrasalarial
B47: C.Extra.05 | F47: Extrasalarial

Sheet DATOS
C2: PERIODO DE REFERENCIA
C3: fecha inicio | D3: =+Inicio!E10 -> 0 | AB3: 5 | AC3: Tipo | AD3: =IFERROR(IF(VLOOKUP(AD$8,TblComplem[],$AB3,0)=0,"",VLOOKUP(AD$8,TblComplem[],$AB3,0)),"") -> Salario Base | AE3: =IFERROR(IF(VLOOKUP(AE$8,TblComplem[],$AB3,0)=0,"",VLOOKUP(AE$8,TblComplem[],$AB3,0)),"") -> Comp. Salarial | AF3: =IFERROR(IF(VLOOKUP(AF$8,TblComplem[],$AB3,0)=0,"",VLOOKUP(AF$8,TblComplem[],$AB3,0)),"") -> Comp. Salarial | AG3: =IFERROR(IF(VLOOKUP(AG$8,TblComplem[],$AB3,0)=0,"",VLOOKUP(AG$8,TblComplem[],$AB3,0)),"") -> Comp. Salarial | AH3: =IFERROR(IF(VLOOKUP(AH$8,TblComplem[],$AB3,0)=0,"",VLOOKUP(AH$8,TblComplem[],$AB3,0)),"") -> Comp. Salarial | AI3: =IFERROR(IF(VLOOKUP(AI$8,TblComplem[],$AB3,0)=0,"",VLOOKUP(AI$8,TblComplem[],$AB3,0)),"") -> Comp. Salarial | AJ3: =IFERROR(IF(VLOOKUP(AJ$8,TblComplem[],$AB3,0)=0,"",VLOOKUP(AJ$8,TblComplem[],$AB3,0)),"") -> Comp. Salarial | AK3: =IFERROR(IF(VLOOKUP(AK$8,TblComplem[],$AB3,0)=0,"",VLOOKUP(AK$8,TblComplem[],$AB3,0)),"") -> Comp. Salarial | ... BM3: =IFERROR(IF(VLOOKUP(BM$8,TblComplem[],$AB3,0)=0,"",VLOOKUP(BM$8,TblComplem[],$AB3,0)),"") -> Extrasalarial | BP3: Nº SC Norm | BQ3: cuando % norm difer 100% y % anualiz es 100%
C4: fecha fin | D4: =+Inicio!G10 -> 0 | AB4: 6 | AC4: Normalizable | AD4: =IFERROR(IF(VLOOKUP(AD$8,TblComplem[],$AB4,0)=0,"",VLOOKUP(AD$8,TblComplem[],$AB4,0)),"") | AE4: =IFERROR(IF(VLOOKUP(AE$8,TblComplem[],$AB4,0)=0,"",VLOOKUP(AE$8,TblComplem[],$AB4,0)),"") | AF4: =IFERROR(IF(VLOOKUP(AF$8,TblComplem[],$AB4,0)=0,"",VLOOKUP(AF$8,TblComplem[],$AB4,0)),"") | AG4: =IFERROR(IF(VLOOKUP(AG$8,TblComplem[],$AB4,0)=0,"",VLOOKUP(AG$8,TblComplem[],$AB4,0)),"") | AH4: =IFERROR(IF(VLOOKUP(AH$8,TblComplem[],$AB4,0)=0,"",VLOOKUP(AH$8,TblComplem[],$AB4,0)),"") | AI4: =IFERROR(IF(VLOOKUP(AI$8,TblComplem[],$AB4,0)=0,"",VLOOKUP(AI$8,TblComplem[],$AB4,0)),"") | AJ4: =IFERROR(IF(VLOOKUP(AJ$8,TblComplem[],$AB4,0)=0,"",VLOOKUP(AJ$8,TblComplem[],$AB4,0)),"") | AK4: =IFERROR(IF(VLOOKUP(AK$8,TblComplem[],$AB4,0)=0,"",VLOOKUP(AK$8,TblComplem[],$AB4,0)),"") | ... BM4: =IFERROR(IF(VLOOKUP(BM$8,TblComplem[],$AB4,0)=0,"",VLOOKUP(BM$8,TblComplem[],$AB4,0)),"") | BP4: Nº SC Anualiz
C5: días | D5: =D4-D3+1 -> 1 | AB5: 7 | AC5: Anualizable | AD5: =IFERROR(IF(VLOOKUP(AD$8,TblComplem[],$AB5,0)=0,"",VLOOKUP(AD$8,TblComplem[],$AB5,0)),"") | AE5: =IFERROR(IF(VLOOKUP(AE$8,TblComplem[],$AB5,0)=0,"",VLOOKUP(AE$8,TblComplem[],$AB5,0)),"") | AF5: =IFERROR(IF(VLOOKUP(AF$8,TblComplem[],$AB5,0)=0,"",VLOOKUP(AF$8,TblComplem[],$AB5,0)),"") | AG5: =IFERROR(IF(VLOOKUP(AG$8,TblComplem[],$AB5,0)=0,"",VLOOKUP(AG$8,TblComplem[],$AB5,0)),"") | AH5: =IFERROR(IF(VLOOKUP(AH$8,TblComplem[],$AB5,0)=0,"",VLOOKUP(AH$8,TblComplem[],$AB5,0)),"") | AI5: =IFERROR(IF(VLOOKUP(AI$8,TblComplem[],$AB5,0)=0,"",VLOOKUP(AI$8,TblComplem[],$AB5,0)),"") | AJ5: =IFERROR(IF(VLOOKUP(AJ$8,TblComplem[],$AB5,0)=0,"",VLOOKUP(AJ$8,TblComplem[],$AB5,0)),"") | AK5: =IFERROR(IF(VLOOKUP(AK$8,TblComplem[],$AB5,0)=0,"",VLOOKUP(AK$8,TblComplem[],$AB5,0)),"") | ... BM5: =IFERROR(IF(VLOOKUP(BM$8,TblComplem[],$AB5,0)=0,"",VLOOKUP(BM$8,TblComplem[],$AB5,0)),"") | BP5: Nº SC Norm y Anualiz
AB6: 2 | AC6: Nombre Corto | AD6: =IFERROR(IF(VLOOKUP(AD$8,TblComplem[],$AB6,0)=0,"",VLOOKUP(AD$8,TblComplem[],$AB6,0)),"") | AE6: =IFERROR(IF(VLOOKUP(AE$8,TblComplem[],$AB6,0)=0,"",VLOOKUP(AE$8,TblComplem[],$AB6,0)),"") | AF6: =IFERROR(IF(VLOOKUP(AF$8,TblComplem[],$AB6,0)=0,"",VLOOKUP(AF$8,TblComplem[],$AB6,0)),"") | AG6: =IFERROR(IF(VLOOKUP(AG$8,TblComplem[],$AB6,0)=0,"",VLOOKUP(AG$8,TblComplem[],$AB6,0)),"") | AH6: =IFERROR(IF(VLOOKUP(AH$8,TblComplem[],$AB6,0)=0,"",VLOOKUP(AH$8,TblComplem[],$AB6,0)),"") | AI6: =IFERROR(IF(VLOOKUP(AI$8,TblComplem[],$AB6,0)=0,"",VLOOKUP(AI$8,TblComplem[],$AB6,0)),"") | AJ6: =IFERROR(IF(VLOOKUP(AJ$8,TblComplem[],$AB6,0)=0,"",VLOOKUP(AJ$8,TblComplem[],$AB6,0)),"") | AK6: =IFERROR(IF(VLOOKUP(AK$8,TblComplem[],$AB6,0)=0,"",VLOOKUP(AK$8,TblComplem[],$AB6,0)),"") | ... BM6: =IFERROR(IF(VLOOKUP(BM$8,TblComplem[],$AB6,0)=0,"",VLOOKUP(BM$8,TblComplem[],$AB6,0)),"")
BY7: Comp. Salarial | CA7: Extrasalarial
B8: id | C8: Sexo | D8: Fecha Nacimiento | E8: Nivel de Estudios | F8: Situación Familiar | G8: Hijos/as | H8: Fecha de Contratación | I8: Fecha Fin Contrato | J8: Fecha de Antigüedad | K8: Fecha Inicio Sit. Contract. | L8: Fecha Fin Sit. Contract. | M8: % de jornada | N8: % jornada reducida | O8: motivo reducción | P8: Clave de Contrato | Q8: Area-empresa | R8: Dpto-empresa | S8: Puesto-empresa | T8: Horario (continuo/partido) | U8: Trabajo a turnos | V8: Escala-empresa | W8: AGRUP. CLAS. PROF. | X8: AGRUP. VALOR. PTO. | Y8: Convenio/Área | Z8: Categoría profesional | AA8: Grupo profesional | AB8: Nivel | AC8: Grupo de Cotización Seg.Social. | AD8: S.BASE | AE8: Conc.Sal.01 | AF8: Conc.Sal.02 | AG8: Conc.Sal.03 | AH8: Conc.Sal.04 | AI8: Conc.Sal.05 | AJ8: Conc.Sal.06 | AK8: Conc.Sal.07 | AL8: Conc.Sal.08 | AM8: Conc.Sal.09 | AN8: Conc.Sal.10 | AO8: Conc.Sal.11 | AP8: Conc.Sal.12 | AQ8: Conc.Sal.13 | AR8: Conc.Sal.14 | AS8: Conc.Sal.15 | AT8: Conc.Sal.16 | AU8: Conc.Sal.17 | AV8: Conc.Sal.18 | AW8: Conc.Sal.19 | AX8: Conc.Sal.20 | AY8: Conc.Sal.21 | AZ8: Conc.Sal.22 | BA8: Conc.Sal.23 | BB8: Conc.Sal.24 | BC8: Conc.Sal.25 | BD8: Conc.Sal.26 | BE8: Conc.Sal.27 | BF8: Conc.Sal.28 | BG8: Conc.Sal.29 | BH8: Conc.Sal.30 | BI8: C.Extra.01 | BJ8: C.Extra.02 | BK8: C.Extra.03 | BL8: C.Extra.04 | BM8: C.Extra.05 | BN8: F.ini.cal | BO8: F.fin.cal | BP8: % normaliz | BQ8: % anualiz | BR8: Check Periodo Ref. | BS8: Check Equiparado | BT8: Check Nº SC Norm | BU8: Check Nº SC Anualiz | BV8: Check Nº SC Norm y Anualiz | BW8: Check Equiparación | BX8: SALARIO BASE Eq | BY8: Tot COMPL.SAL Eq | BZ8: TOTAL SALARIO Eq | CA8: Tot Extrasalarial Eq | CB8: TOTAL Retrib Eq | CC8: SALARIO BASE Ef | CD8: Tot COMPL.SAL Ef | CE8: TOTAL SALARIO Ef | CF8: Tot Extrasalarial Ef | CG8: TOTAL Retrib Ef | CH8: DIAS TRABAJ. EN EL AÑO | CI8: REPET. | CJ8: Edad | CK8: Antigüedad | CL8: Jornada | CM8: Contrato | CN8: Intervalo Edad | CO8: Intervalo Antigüedad
BN9: =+MAX($D$3,DATOS_[[#This Row],[Fecha Inicio Sit. Contract.]]) -> 0 | BO9: =+MIN($D$4,DATOS_[[#This Row],[Fecha Fin Sit. Contract.]]) -> 0 | BP9: =+DATOS_[[#This Row],[% de jornada]]*IF(DATOS_[[#This Row],[% jornada reducida]]="",1,DATOS_[[#This Row],[% jornada reducida]]) -> 0 | BQ9: =+(DATOS_[[#This Row],[F.fin.cal]]-DATOS_[[#This Row],[F.ini.cal]]+1)/($D$4-$D$3+1) -> 1 | BR9: =IF(OR(AND(DATOS_[[#This Row],[Fecha Fin Contrato]]<$D$3,DATOS_[[#This Row],[Fecha Fin Contrato]]<>""),DATOS_[[#This Row],[Fecha de Contratación]]>$D$4),"Fuera","Dentro") -> Dentro | BS9: {=IF(MAX(IF(DATOS_[id]=DATOS_[[#This Row],[id]],DATOS_[F.fin.cal]))=DATOS_[[#This Row],[F.fin.cal]],"Sí","NO")} -> Sí | BT9: =IF(AND(DATOS_[[#This Row],[% normaliz]]<>1,DATOS_[[#This Row],[% anualiz]]=1),"Sí","NO") -> Sí | BU9: =IF(AND(DATOS_[[#This Row],[% normaliz]]=1,DATOS_[[#This Row],[% anualiz]]<>1),"Sí","NO") -> NO | BV9: =IF(AND(DATOS_[[#This Row],[% normaliz]]<>1,DATOS_[[#This Row],[% anualiz]]<>1),"Sí","NO") -> NO | BW9: =+IF(DATOS_[[#This Row],[% normaliz]]*DATOS_[[#This Row],[% anualiz]]=1,"NO","Sí") -> Sí | BX9: =(DATOS_[[#This Row],[S.BASE]]*(1/DATOS_[[#This Row],[% normaliz]])*(1/DATOS_[[#This Row],[% anualiz]]))*IF(DATOS_[[#This Row],[Check Equiparado]]="Sí",1,0) -> #DIV/0! | BY9: =(SUMPRODUCT((RngTipo=$BY$7)*(rngAnualizable="Sí")*(rngNormalizable="Sí")*(DATOS_[[#This Row],[Conc.Sal.01]:[C.Extra.05]]))*(1/DATOS_[[#This Row],[% anualiz]])*(1/DATOS_[[#This Row],[% normaliz]]) +SUMPRODUCT((RngTipo=$BY$7)*(rngAnualizable="Sí")*(rngNormalizable="No")*(DATOS_[[#This Row],[Conc.Sal.01]:[C.Extra.05]]))*(1/DATOS_[[#This Row],[% anualiz]]) +SUMPRODUCT((RngTipo=$BY$7)*(rngAnualizable="No")*(rngNormalizable="Sí")*(DATOS_[[#This Row],[Conc.Sal.01]:[C.Extra.05]]))*(1/DATOS_[[#This Row],[% normaliz]]) +SUMPRODUCT((RngTipo=$BY$7)*(rngAnualizable="No")*(rngNormalizable="No")*(DATOS_[[#This Row],[Conc.Sal.01]:[C.Extra.05]]))) *IF(DATOS_[[#This Row],[Check Equiparado]]="Sí",1,0) -> #DIV/0! | BZ9: =+DATOS_[[#This Row],[SALARIO BASE Eq]]+DATOS_[[#This Row],[Tot COMPL.SAL Eq]] -> #DIV/0! | CA9: {=(SUMPRODUCT((RngTipo=$CA$7)*(rngAnualizable="Sí")*(rngNormalizable="Sí")*(DATOS_[[#This Row],[Conc.Sal.01]:[C.Extra.05]]))*(1/DATOS_[[#This Row],[% anualiz]])*(1/DATOS_[[#This Row],[% normaliz]]) +SUMPRODUCT((RngTipo=$CA$7)*(rngAnualizable="Sí")*(rngNormalizable="No")*(DATOS_[[#This Row],[Conc.Sal.01]:[C.Extra.05]]))*(1/DATOS_[[#This Row],[% anualiz]]) +SUMPRODUCT((RngTipo=$CA$7)*(rngAnualizable="No")*(rngNormalizable="Sí")*(DATOS_[[#This Row],[Conc.Sal.01]:[C.Extra.05]]))*(1/DATOS_[[#This Row],[% normaliz]]) +SUMPRODUCT((RngTipo=$CA$7)*(rngAnualizable="No")*(rngNormalizable="No")*(DATOS_[[#This Row],[Conc.Sal.01]:[C.Extra.05]]))) *IF(DATOS_[[#This Row],[Check Equiparado]]="Sí",1,0)} -> #DIV/0! | CB9: =+DATOS_[[#This Row],[TOTAL SALARIO Eq]]+DATOS_[[#This Row],[Tot Extrasalarial Eq]] -> #DIV/0! | CC9: =DATOS_[[#This Row],[S.BASE]] -> 0 | CD9: =+SUM(DATOS_[[#This Row],[Conc.Sal.01]:[Conc.Sal.30]]) -> 0 | CE9: =+DATOS_[[#This Row],[SALARIO BASE Ef]]+DATOS_[[#This Row],[Tot COMPL.SAL Ef]] -> 0 | CF9: =+SUM(DATOS_[[#This Row],[C.Extra.01]:[C.Extra.05]]) -> 0 | CG9: =+DATOS_[[#This Row],[TOTAL SALARIO Ef]]+DATOS_[[#This Row],[Tot Extrasalarial Ef]] -> 0 | CH9: =MIN(IF(DATOS_[[#This Row],[Fecha Fin Contrato]]="",$D$4,DATOS_[[#This Row],[Fecha Fin Contrato]]),$D$4)-MAX(DATOS_[[#This Row],[Fecha de Contratación]],$D$3)+1 -> 1 | CI9: =IF(COUNTIFS(DATOS_[id],DATOS_[[#This Row],[id]])>1,DATOS_[[#This Row],[id]],"") | CJ9: =(Inicio!$G$10-DATOS_[[#This Row],[Fecha Nacimiento]])/365.25 -> 0 | CK9: =(Inicio!$G$10-DATOS_[[#This Row],[Fecha de Antigüedad]])/365.25 -> 0 | CL9: =+VLOOKUP(DATOS_[[#This Row],[Clave de Contrato]],TblTiposContrato13[],3,0) -> #N/A | CM9: =+VLOOKUP(DATOS_[[#This Row],[Clave de Contrato]],TblTiposContrato13[],4,0) -> #N/A | CN9: =VLOOKUP(DATOS_[[#This Row],[Edad]],CONTRATOS!TblRngEdad,2,1) -> 20 o menos | CO9: =VLOOKUP(DATOS_[[#This Row],[Antigüedad]],TblRngAntg14[],2,1) -> 0 a 1 años
BN10: =+MAX($D$3,DATOS_[[#This Row],[Fecha Inicio Sit. Contract.]]) -> 0 | BO10: =+MIN($D$4,DATOS_[[#This Row],[Fecha Fin Sit. Contract.]]) -> 0 | BP10: =+DATOS_[[#This Row],[% de jornada]]*IF(DATOS_[[#This Row],[% jornada reducida]]="",1,DATOS_[[#This Row],[% jornada reducida]]) -> 0 | BQ10: =+(DATOS_[[#This Row],[F.fin.cal]]-DATOS_[[#This Row],[F.ini.cal]]+1)/($D$4-$D$3+1) -> 1 | BR10: =IF(OR(AND(DATOS_[[#This Row],[Fecha Fin Contrato]]<$D$3,DATOS_[[#This Row],[Fecha Fin Contrato]]<>""),DATOS_[[#This Row],[Fecha de Contratación]]>$D$4),"Fuera","Dentro") -> Dentro | BS10: {=IF(MAX(IF(DATOS_[id]=DATOS_[[#This Row],[id]],DATOS_[F.fin.cal]))=DATOS_[[#This Row],[F.fin.cal]],"Sí","NO")} -> Sí | BT10: =IF(AND(DATOS_[[#This Row],[% normaliz]]<>1,DATOS_[[#This Row],[% anualiz]]=1),"Sí","NO") -> Sí | BU10: =IF(AND(DATOS_[[#This Row],[% normaliz]]=1,DATOS_[[#This Row],[% anualiz]]<>1),"Sí","NO") -> NO | BV10: =IF(AND(DATOS_[[#This Row],[% normaliz]]<>1,DATOS_[[#This Row],[% anualiz]]<>1),"Sí","NO") -> NO | BW10: =+IF(DATOS_[[#This Row],[% normaliz]]*DATOS_[[#This Row],[% anualiz]]=1,"NO","Sí") -> Sí | BX10: =(DATOS_[[#This Row],[S.BASE]]*(1/DATOS_[[#This Row],[% normaliz]])*(1/DATOS_[[#This Row],[% anualiz]]))*IF(DATOS_[[#This Row],[Check Equiparado]]="Sí",1,0) -> #DIV/0! | BY10: =(SUMPRODUCT((RngTipo=$BY$7)*(rngAnualizable="Sí")*(rngNormalizable="Sí")*(DATOS_[[#This Row],[Conc.Sal.01]:[C.Extra.05]]))*(1/DATOS_[[#This Row],[% anualiz]])*(1/DATOS_[[#This Row],[% normaliz]]) +SUMPRODUCT((RngTipo=$BY$7)*(rngAnualizable="Sí")*(rngNormalizable="No")*(DATOS_[[#This Row],[Conc.Sal.01]:[C.Extra.05]]))*(1/DATOS_[[#This Row],[% anualiz]]) +SUMPRODUCT((RngTipo=$BY$7)*(rngAnualizable="No")*(rngNormalizable="Sí")*(DATOS_[[#This Row],[Conc.Sal.01]:[C.Extra.05]]))*(1/DATOS_[[#This Row],[% normaliz]]) +SUMPRODUCT((RngTipo=$BY$7)*(rngAnualizable="No")*(rngNormalizable="No")*(DATOS_[[#This Row],[Conc.Sal.01]:[C.Extra.05]]))) *IF(DATOS_[[#This Row],[Check Equiparado]]="Sí",1,0) -> #DIV/0! | BZ10: =+DATOS_[[#This Row],[SALARIO BASE Eq]]+DATOS_[[#This Row],[Tot COMPL.SAL Eq]] -> #DIV/0! | CA10: {=(SUMPRODUCT((RngTipo=$CA$7)*(rngAnualizable="Sí")*(rngNormalizable="Sí")*(DATOS_[[#This Row],[Conc.Sal.01]:[C.Extra.05]]))*(1/DATOS_[[#This Row],[% anualiz]])*(1/DATOS_[[#This Row],[% normaliz]]) +SUMPRODUCT((RngTipo=$CA$7)*(rngAnualizable="Sí")*(rngNormalizable="No")*(DATOS_[[#This Row],[Conc.Sal.01]:[C.Extra.05]]))*(1/DATOS_[[#This Row],[% anualiz]]) +SUMPRODUCT((RngTipo=$CA$7)*(rngAnualizable="No")*(rngNormalizable="Sí")*(DATOS_[[#This Row],[Conc.Sal.01]:[C.Extra.05]]))*(1/DATOS_[[#This Row],[% normaliz]]) +SUMPRODUCT((RngTipo=$CA$7)*(rngAnualizable="No")*(rngNormalizable="No")*(DATOS_[[#This Row],[Conc.Sal.01]:[C.Extra.05]]))) *IF(DATOS_[[#This Row],[Check Equiparado]]="Sí",1,0)} -> #DIV/0! | CB10: =+DATOS_[[#This Row],[TOTAL SALARIO Eq]]+DATOS_[[#This Row],[Tot Extrasalarial Eq]] -> #DIV/0! | CC10: =DATOS_[[#This Row],[S.BASE]] -> 0 | CD10: =+SUM(DATOS_[[#This Row],[Conc.Sal.01]:[Conc.Sal.30]]) -> 0 | CE10: =+DATOS_[[#This Row],[SALARIO BASE Ef]]+DATOS_[[#This Row],[Tot COMPL.SAL Ef]] -> 0 | CF10: =+SUM(DATOS_[[#This Row],[C.Extra.01]:[C.Extra.05]]) -> 0 | CG10: =+DATOS_[[#This Row],[TOTAL SALARIO Ef]]+DATOS_[[#This Row],[Tot Extrasalarial Ef]] -> 0 | CH10: =MIN(IF(DATOS_[[#This Row],[Fecha Fin Contrato]]="",$D$4,DATOS_[[#This Row],[Fecha Fin Contrato]]),$D$4)-MAX(DATOS_[[#This Row],[Fecha de Contratación]],$D$3)+1 -> 1 | CI10: =IF(COUNTIFS(DATOS_[id],DATOS_[[#This Row],[id]])>1,DATOS_[[#This Row],[id]],"") | CJ10: =(Inicio!$G$10-DATOS_[[#This Row],[Fecha Nacimiento]])/365.25 -> 0 | CK10: =(Inicio!$G$10-DATOS_[[#This Row],[Fecha de Antigüedad]])/365.25 -> 0 | CL10: =+VLOOKUP(DATOS_[[#This Row],[Clave de Contrato]],TblTiposContrato13[],3,0) -> #N/A | CM10: =+VLOOKUP(DATOS_[[#This Row],[Clave de Contrato]],TblTiposContrato13[],4,0) -> #N/A | CN10: =VLOOKUP(DATOS_[[#This Row],[Edad]],CONTRATOS!TblRngEdad,2,1) -> 20 o menos | CO10: =VLOOKUP(DATOS_[[#This Row],[Antigüedad]],TblRngAntg14[],2,1) -> 0 a 1 años
BN11: =+MAX($D$3,DATOS_[[#This Row],[Fecha Inicio Sit. Contract.]]) -> 0 | BO11: =+MIN($D$4,DATOS_[[#This Row],[Fecha Fin Sit. Contract.]]) -> 0 | BP11: =+DATOS_[[#This Row],[% de jornada]]*IF(DATOS_[[#This Row],[% jornada reducida]]="",1,DATOS_[[#This Row],[% jornada reducida]]) -> 0 | BQ11: =+(DATOS_[[#This Row],[F.fin.cal]]-DATOS_[[#This Row],[F.ini.cal]]+1)/($D$4-$D$3+1) -> 1 | BR11: =IF(OR(AND(DATOS_[[#This Row],[Fecha Fin Contrato]]<$D$3,DATOS_[[#This Row],[Fecha Fin Contrato]]<>""),DATOS_[[#This Row],[Fecha de Contratación]]>$D$4),"Fuera","Dentro") -> Dentro | BS11: {=IF(MAX(IF(DATOS_[id]=DATOS_[[#This Row],[id]],DATOS_[F.fin.cal]))=DATOS_[[#This Row],[F.fin.cal]],"Sí","NO")} -> Sí | BT11: =IF(AND(DATOS_[[#This Row],[% normaliz]]<>1,DATOS_[[#This Row],[% anualiz]]=1),"Sí","NO") -> Sí | BU11: =IF(AND(DATOS_[[#This Row],[% normaliz]]=1,DATOS_[[#This Row],[% anualiz]]<>1),"Sí","NO") -> NO | BV11: =IF(AND(DATOS_[[#This Row],[% normaliz]]<>1,DATOS_[[#This Row],[% anualiz]]<>1),"Sí","NO") -> NO | BW11: =+IF(DATOS_[[#This Row],[% normaliz]]*DATOS_[[#This Row],[% anualiz]]=1,"NO","Sí") -> Sí | BX11: =(DATOS_[[#This Row],[S.BASE]]*(1/DATOS_[[#This Row],[% normaliz]])*(1/DATOS_[[#This Row],[% anualiz]]))*IF(DATOS_[[#This Row],[Check Equiparado]]="Sí",1,0) -> #DIV/0! | BY11: =(SUMPRODUCT((RngTipo=$BY$7)*(rngAnualizable="Sí")*(rngNormalizable="Sí")*(DATOS_[[#This Row],[Conc.Sal.01]:[C.Extra.05]]))*(1/DATOS_[[#This Row],[% anualiz]])*(1/DATOS_[[#This Row],[% normaliz]]) +SUMPRODUCT((RngTipo=$BY$7)*(rngAnualizable="Sí")*(rngNormalizable="No")*(DATOS_[[#This Row],[Conc.Sal.01]:[C.Extra.05]]))*(1/DATOS_[[#This Row],[% anualiz]]) +SUMPRODUCT((RngTipo=$BY$7)*(rngAnualizable="No")*(rngNormalizable="Sí")*(DATOS_[[#This Row],[Conc.Sal.01]:[C.Extra.05]]))*(1/DATOS_[[#This Row],[% normaliz]]) +SUMPRODUCT((RngTipo=$BY$7)*(rngAnualizable="No")*(rngNormalizable="No")*(DATOS_[[#This Row],[Conc.Sal.01]:[C.Extra.05]]))) *IF(DATOS_[[#This Row],[Check Equiparado]]="Sí",1,0) -> #DIV/0! | BZ11: =+DATOS_[[#This Row],[SALARIO BASE Eq]]+DATOS_[[#This Row],[Tot COMPL.SAL Eq]] -> #DIV/0! | CA11: {=(SUMPRODUCT((RngTipo=$CA$7)*(rngAnualizable="Sí")*(rngNormalizable="Sí")*(DATOS_[[#This Row],[Conc.Sal.01]:[C.Extra.05]]))*(1/DATOS_[[#This Row],[% anualiz]])*(1/DATOS_[[#This Row],[% normaliz]]) +SUMPRODUCT((RngTipo=$CA$7)*(rngAnualizable="Sí")*(rngNormalizable="No")*(DATOS_[[#This Row],[Conc.Sal.01]:[C.Extra.05]]))*(1/DATOS_[[#This Row],[% anualiz]]) +SUMPRODUCT((RngTipo=$CA$7)*(rngAnualizable="No")*(rngNormalizable="Sí")*(DATOS_[[#This Row],[Conc.Sal.01]:[C.Extra.05]]))*(1/DATOS_[[#This Row],[% normaliz]]) +SUMPRODUCT((RngTipo=$CA$7)*(rngAnualizable="No")*(rngNormalizable="No")*(DATOS_[[#This Row],[Conc.Sal.01]:[C.Extra.05]]))) *IF(DATOS_[[#This Row],[Check Equiparado]]="Sí",1,0)} -> #DIV/0! | CB11: =+DATOS_[[#This Row],[TOTAL SALARIO Eq]]+DATOS_[[#This Row],[Tot Extrasalarial Eq]] -> #DIV/0! | CC11: =DATOS_[[#This Row],[S.BASE]] -> 0 | CD11: =+SUM(DATOS_[[#This Row],[Conc.Sal.01]:[Conc.Sal.30]]) -> 0 | CE11: =+DATOS_[[#This Row],[SALARIO BASE Ef]]+DATOS_[[#This Row],[Tot COMPL.SAL Ef]] -> 0 | CF11: =+SUM(DATOS_[[#This Row],[C.Extra.01]:[C.Extra.05]]) -> 0 | CG11: =+DATOS_[[#This Row],[TOTAL SALARIO Ef]]+DATOS_[[#This Row],[Tot Extrasalarial Ef]] -> 0 | CH11: =MIN(IF(DATOS_[[#This Row],[Fecha Fin Contrato]]="",$D$4,DATOS_[[#This Row],[Fecha Fin Contrato]]),$D$4)-MAX(DATOS_[[#This Row],[Fecha de Contratación]],$D$3)+1 -> 1 | CI11: =IF(COUNTIFS(DATOS_[id],DATOS_[[#This Row],[id]])>1,DATOS_[[#This Row],[id]],"") | CJ11: =(Inicio!$G$10-DATOS_[[#This Row],[Fecha Nacimiento]])/365.25 -> 0 | CK11: =(Inicio!$G$10-DATOS_[[#This Row],[Fecha de Antigüedad]])/365.25 -> 0 | CL11: =+VLOOKUP(DATOS_[[#This Row],[Clave de Contrato]],TblTiposContrato13[],3,0) -> #N/A | CM11: =+VLOOKUP(DATOS_[[#This Row],[Clave de Contrato]],TblTiposContrato13[],4,0) -> #N/A | CN11: =VLOOKUP(DATOS_[[#This Row],[Edad]],CONTRATOS!TblRngEdad,2,1) -> 20 o menos | CO11: =VLOOKUP(DATOS_[[#This Row],[Antigüedad]],TblRngAntg14[],2,1) -> 0 a 1 años
BN12: =+MAX($D$3,DATOS_[[#This Row],[Fecha Inicio Sit. Contract.]]) -> 0 | BO12: =+MIN($D$4,DATOS_[[#This Row],[Fecha Fin Sit. Contract.]]) -> 0 | BP12: =+DATOS_[[#This Row],[% de jornada]]*IF(DATOS_[[#This Row],[% jornada reducida]]="",1,DATOS_[[#This Row],[% jornada reducida]]) -> 0 | BQ12: =+(DATOS_[[#This Row],[F.fin.cal]]-DATOS_[[#This Row],[F.ini.cal]]+1)/($D$4-$D$3+1) -> 1 | BR12: =IF(OR(AND(DATOS_[[#This Row],[Fecha Fin Contrato]]<$D$3,DATOS_[[#This Row],[Fecha Fin Contrato]]<>""),DATOS_[[#This Row],[Fecha de Contratación]]>$D$4),"Fuera","Dentro") -> Dentro | BS12: {=IF(MAX(IF(DATOS_[id]=DATOS_[[#This Row],[id]],DATOS_[F.fin.cal]))=DATOS_[[#This Row],[F.fin.cal]],"Sí","NO")} -> Sí | BT12: =IF(AND(DATOS_[[#This Row],[% normaliz]]<>1,DATOS_[[#This Row],[% anualiz]]=1),"Sí","NO") -> Sí | BU12: =IF(AND(DATOS_[[#This Row],[% normaliz]]=1,DATOS_[[#This Row],[% anualiz]]<>1),"Sí","NO") -> NO | BV12: =IF(AND(DATOS_[[#This Row],[% normaliz]]<>1,DATOS_[[#This Row],[% anualiz]]<>1),"Sí","NO") -> NO | BW12: =+IF(DATOS_[[#This Row],[% normaliz]]*DATOS_[[#This Row],[% anualiz]]=1,"NO","Sí") -> Sí | BX12: =(DATOS_[[#This Row],[S.BASE]]*(1/DATOS_[[#This Row],[% normaliz]])*(1/DATOS_[[#This Row],[% anualiz]]))*IF(DATOS_[[#This Row],[Check Equiparado]]="Sí",1,0) -> #DIV/0! | BY12: =(SUMPRODUCT((RngTipo=$BY$7)*(rngAnualizable="Sí")*(rngNormalizable="Sí")*(DATOS_[[#This Row],[Conc.Sal.01]:[C.Extra.05]]))*(1/DATOS_[[#This Row],[% anualiz]])*(1/DATOS_[[#This Row],[% normaliz]]) +SUMPRODUCT((RngTipo=$BY$7)*(rngAnualizable="Sí")*(rngNormalizable="No")*(DATOS_[[#This Row],[Conc.Sal.01]:[C.Extra.05]]))*(1/DATOS_[[#This Row],[% anualiz]]) +SUMPRODUCT((RngTipo=$BY$7)*(rngAnualizable="No")*(rngNormalizable="Sí")*(DATOS_[[#This Row],[Conc.Sal.01]:[C.Extra.05]]))*(1/DATOS_[[#This Row],[% normaliz]]) +SUMPRODUCT((RngTipo=$BY$7)*(rngAnualizable="No")*(rngNormalizable="No")*(DATOS_[[#This Row],[Conc.Sal.01]:[C.Extra.05]]))) *IF(DATOS_[[#This Row],[Check Equiparado]]="Sí",1,0) -> #DIV/0! | BZ12: =+DATOS_[[#This Row],[SALARIO BASE Eq]]+DATOS_[[#This Row],[Tot COMPL.SAL Eq]] -> #DIV/0! | CA12: {=(SUMPRODUCT((RngTipo=$CA$7)*(rngAnualizable="Sí")*(rngNormalizable="Sí")*(DATOS_[[#This Row],[Conc.Sal.01]:[C.Extra.05]]))*(1/DATOS_[[#This Row],[% anualiz]])*(1/DATOS_[[#This Row],[% normaliz]]) +SUMPRODUCT((RngTipo=$CA$7)*(rngAnualizable="Sí")*(rngNormalizable="No")*(DATOS_[[#This Row],[Conc.Sal.01]:[C.Extra.05]]))*(1/DATOS_[[#This Row],[% anualiz]]) +SUMPRODUCT((RngTipo=$CA$7)*(rngAnualizable="No")*(rngNormalizable="Sí")*(DATOS_[[#This Row],[Conc.Sal.01]:[C.Extra.05]]))*(1/DATOS_[[#This Row],[% normaliz]]) +SUMPRODUCT((RngTipo=$CA$7)*(rngAnualizable="No")*(rngNormalizable="No")*(DATOS_[[#This Row],[Conc.Sal.01]:[C.Extra.05]]))) *IF(DATOS_[[#This Row],[Check Equiparado]]="Sí",1,0)} -> #DIV/0! | CB12: =+DATOS_[[#This Row],[TOTAL SALARIO Eq]]+DATOS_[[#This Row],[Tot Extrasalarial Eq]] -> #DIV/0! | CC12: =DATOS_[[#This Row],[S.BASE]] -> 0 | CD12: =+SUM(DATOS_[[#This Row],[Conc.Sal.01]:[Conc.Sal.30]]) -> 0 | CE12: =+DATOS_[[#This Row],[SALARIO BASE Ef]]+DATOS_[[#This Row],[Tot COMPL.SAL Ef]] -> 0 | CF12: =+SUM(DATOS_[[#This Row],[C.Extra.01]:[C.Extra.05]]) -> 0 | CG12: =+DATOS_[[#This Row],[TOTAL SALARIO Ef]]+DATOS_[[#This Row],[Tot Extrasalarial Ef]] -> 0 | CH12: =MIN(IF(DATOS_[[#This Row],[Fecha Fin Contrato]]="",$D$4,DATOS_[[#This Row],[Fecha Fin Contrato]]),$D$4)-MAX(DATOS_[[#This Row],[Fecha de Contratación]],$D$3)+1 -> 1 | CI12: =IF(COUNTIFS(DATOS_[id],DATOS_[[#This Row],[id]])>1,DATOS_[[#This Row],[id]],"") | CJ12: =(Inicio!$G$10-DATOS_[[#This Row],[Fecha Nacimiento]])/365.25 -> 0 | CK12: =(Inicio!$G$10-DATOS_[[#This Row],[Fecha de Antigüedad]])/365.25 -> 0 | CL12: =+VLOOKUP(DATOS_[[#This Row],[Clave de Contrato]],TblTiposContrato13[],3,0) -> #N/A | CM12: =+VLOOKUP(DATOS_[[#This Row],[Clave de Contrato]],TblTiposContrato13[],4,0) -> #N/A | CN12: =VLOOKUP(DATOS_[[#This Row],[Edad]],CONTRATOS!TblRngEdad,2,1) -> 20 o menos | CO12: =VLOOKUP(DATOS_[[#This Row],[Antigüedad]],TblRngAntg14[],2,1) -> 0 a 1 años
BN13: =+MAX($D$3,DATOS_[[#This Row],[Fecha Inicio Sit. Contract.]]) -> 0 | BO13: =+MIN($D$4,DATOS_[[#This Row],[Fecha Fin Sit. Contract.]]) -> 0 | BP13: =+DATOS_[[#This Row],[% de jornada]]*IF(DATOS_[[#This Row],[% jornada reducida]]="",1,DATOS_[[#This Row],[% jornada reducida]]) -> 0 | BQ13: =+(DATOS_[[#This Row],[F.fin.cal]]-DATOS_[[#This Row],[F.ini.cal]]+1)/($D$4-$D$3+1) -> 1 | BR13: =IF(OR(AND(DATOS_[[#This Row],[Fecha Fin Contrato]]<$D$3,DATOS_[[#This Row],[Fecha Fin Contrato]]<>""),DATOS_[[#This Row],[Fecha de Contratación]]>$D$4),"Fuera","Dentro") -> Dentro | BS13: {=IF(MAX(IF(DATOS_[id]=DATOS_[[#This Row],[id]],DATOS_[F.fin.cal]))=DATOS_[[#This Row],[F.fin.cal]],"Sí","NO")} -> Sí | BT13: =IF(AND(DATOS_[[#This Row],[% normaliz]]<>1,DATOS_[[#This Row],[% anualiz]]=1),"Sí","NO") -> Sí | BU13: =IF(AND(DATOS_[[#This Row],[% normaliz]]=1,DATOS_[[#This Row],[% anualiz]]<>1),"Sí","NO") -> NO | BV13: =IF(AND(DATOS_[[#This Row],[% normaliz]]<>1,DATOS_[[#This Row],[% anualiz]]<>1),"Sí","NO") -> NO | BW13: =+IF(DATOS_[[#This Row],[% normaliz]]*DATOS_[[#This Row],[% anualiz]]=1,"NO","Sí") -> Sí | BX13: =(DATOS_[[#This Row],[S.BASE]]*(1/DATOS_[[#This Row],[% normaliz]])*(1/DATOS_[[#This Row],[% anualiz]]))*IF(DATOS_[[#This Row],[Check Equiparado]]="Sí",1,0) -> #DIV/0! | BY13: =(SUMPRODUCT((RngTipo=$BY$7)*(rngAnualizable="Sí")*(rngNormalizable="Sí")*(DATOS_[[#This Row],[Conc.Sal.01]:[C.Extra.05]]))*(1/DATOS_[[#This Row],[% anualiz]])*(1/DATOS_[[#This Row],[% normaliz]]) +SUMPRODUCT((RngTipo=$BY$7)*(rngAnualizable="Sí")*(rngNormalizable="No")*(DATOS_[[#This Row],[Conc.Sal.01]:[C.Extra.05]]))*(1/DATOS_[[#This Row],[% anualiz]]) +SUMPRODUCT((RngTipo=$BY$7)*(rngAnualizable="No")*(rngNormalizable="Sí")*(DATOS_[[#This Row],[Conc.Sal.01]:[C.Extra.05]]))*(1/DATOS_[[#This Row],[% normaliz]]) +SUMPRODUCT((RngTipo=$BY$7)*(rngAnualizable="No")*(rngNormalizable="No")*(DATOS_[[#This Row],[Conc.Sal.01]:[C.Extra.05]]))) *IF(DATOS_[[#This Row],[Check Equiparado]]="Sí",1,0) -> #DIV/0! | BZ13: =+DATOS_[[#This Row],[SALARIO BASE Eq]]+DATOS_[[#This Row],[Tot COMPL.SAL Eq]] -> #DIV/0! | CA13: {=(SUMPRODUCT((RngTipo=$CA$7)*(rngAnualizable="Sí")*(rngNormalizable="Sí")*(DATOS_[[#This Row],[Conc.Sal.01]:[C.Extra.05]]))*(1/DATOS_[[#This Row],[% anualiz]])*(1/DATOS_[[#This Row],[% normaliz]]) +SUMPRODUCT((RngTipo=$CA$7)*(rngAnualizable="Sí")*(rngNormalizable="No")*(DATOS_[[#This Row],[Conc.Sal.01]:[C.Extra.05]]))*(1/DATOS_[[#This Row],[% anualiz]]) +SUMPRODUCT((RngTipo=$CA$7)*(rngAnualizable="No")*(rngNormalizable="Sí")*(DATOS_[[#This Row],[Conc.Sal.01]:[C.Extra.05]]))*(1/DATOS_[[#This Row],[% normaliz]]) +SUMPRODUCT((RngTipo=$CA$7)*(rngAnualizable="No")*(rngNormalizable="No")*(DATOS_[[#This Row],[Conc.Sal.01]:[C.Extra.05]]))) *IF(DATOS_[[#This Row],[Check Equiparado]]="Sí",1,0)} -> #DIV/0! | CB13: =+DATOS_[[#This Row],[TOTAL SALARIO Eq]]+DATOS_[[#This Row],[Tot Extrasalarial Eq]] -> #DIV/0! | CC13: =DATOS_[[#This Row],[S.BASE]] -> 0 | CD13: =+SUM(DATOS_[[#This Row],[Conc.Sal.01]:[Conc.Sal.30]]) -> 0 | CE13: =+DATOS_[[#This Row],[SALARIO BASE Ef]]+DATOS_[[#This Row],[Tot COMPL.SAL Ef]] -> 0 | CF13: =+SUM(DATOS_[[#This Row],[C.Extra.01]:[C.Extra.05]]) -> 0 | CG13: =+DATOS_[[#This Row],[TOTAL SALARIO Ef]]+DATOS_[[#This Row],[Tot Extrasalarial Ef]] -> 0 | CH13: =MIN(IF(DATOS_[[#This Row],[Fecha Fin Contrato]]="",$D$4,DATOS_[[#This Row],[Fecha Fin Contrato]]),$D$4)-MAX(DATOS_[[#This Row],[Fecha de Contratación]],$D$3)+1 -> 1 | CI13: =IF(COUNTIFS(DATOS_[id],DATOS_[[#This Row],[id]])>1,DATOS_[[#This Row],[id]],"") | CJ13: =(Inicio!$G$10-DATOS_[[#This Row],[Fecha Nacimiento]])/365.25 -> 0 | CK13: =(Inicio!$G$10-DATOS_[[#This Row],[Fecha de Antigüedad]])/365.25 -> 0 | CL13: =+VLOOKUP(DATOS_[[#This Row],[Clave de Contrato]],TblTiposContrato13[],3,0) -> #N/A | CM13: =+VLOOKUP(DATOS_[[#This Row],[Clave de Contrato]],TblTiposContrato13[],4,0) -> #N/A | CN13: =VLOOKUP(DATOS_[[#This Row],[Edad]],CONTRATOS!TblRngEdad,2,1) -> 20 o menos | CO13: =VLOOKUP(DATOS_[[#This Row],[Antigüedad]],TblRngAntg14[],2,1) -> 0 a 1 años
BN14: =+MAX($D$3,DATOS_[[#This Row],[Fecha Inicio Sit. Contract.]]) -> 0 | BO14: =+MIN($D$4,DATOS_[[#This Row],[Fecha Fin Sit. Contract.]]) -> 0 | BP14: =+DATOS_[[#This Row],[% de jornada]]*IF(DATOS_[[#This Row],[% jornada reducida]]="",1,DATOS_[[#This Row],[% jornada reducida]]) -> 0 | BQ14: =+(DATOS_[[#This Row],[F.fin.cal]]-DATOS_[[#This Row],[F.ini.cal]]+1)/($D$4-$D$3+1) -> 1 | BR14: =IF(OR(AND(DATOS_[[#This Row],[Fecha Fin Contrato]]<$D$3,DATOS_[[#This Row],[Fecha Fin Contrato]]<>""),DATOS_[[#This Row],[Fecha de Contratación]]>$D$4),"Fuera","Dentro") -> Dentro | BS14: {=IF(MAX(IF(DATOS_[id]=DATOS_[[#This Row],[id]],DATOS_[F.fin.cal]))=DATOS_[[#This Row],[F.fin.cal]],"Sí","NO")} -> Sí | BT14: =IF(AND(DATOS_[[#This Row],[% normaliz]]<>1,DATOS_[[#This Row],[% anualiz]]=1),"Sí","NO") -> Sí | BU14: =IF(AND(DATOS_[[#This Row],[% normaliz]]=1,DATOS_[[#This Row],[% anualiz]]<>1),"Sí","NO") -> NO | BV14: =IF(AND(DATOS_[[#This Row],[% normaliz]]<>1,DATOS_[[#This Row],[% anualiz]]<>1),"Sí","NO") -> NO | BW14: =+IF(DATOS_[[#This Row],[% normaliz]]*DATOS_[[#This Row],[% anualiz]]=1,"NO","Sí") -> Sí | BX14: =(DATOS_[[#This Row],[S.BASE]]*(1/DATOS_[[#This Row],[% normaliz]])*(1/DATOS_[[#This Row],[% anualiz]]))*IF(DATOS_[[#This Row],[Check Equiparado]]="Sí",1,0) -> #DIV/0! | BY14: =(SUMPRODUCT((RngTipo=$BY$7)*(rngAnualizable="Sí")*(rngNormalizable="Sí")*(DATOS_[[#This Row],[Conc.Sal.01]:[C.Extra.05]]))*(1/DATOS_[[#This Row],[% anualiz]])*(1/DATOS_[[#This Row],[% normaliz]]) +SUMPRODUCT((RngTipo=$BY$7)*(rngAnualizable="Sí")*(rngNormalizable="No")*(DATOS_[[#This Row],[Conc.Sal.01]:[C.Extra.05]]))*(1/DATOS_[[#This Row],[% anualiz]]) +SUMPRODUCT((RngTipo=$BY$7)*(rngAnualizable="No")*(rngNormalizable="Sí")*(DATOS_[[#This Row],[Conc.Sal.01]:[C.Extra.05]]))*(1/DATOS_[[#This Row],[% normaliz]]) +SUMPRODUCT((RngTipo=$BY$7)*(rngAnualizable="No")*(rngNormalizable="No")*(DATOS_[[#This Row],[Conc.Sal.01]:[C.Extra.05]]))) *IF(DATOS_[[#This Row],[Check Equiparado]]="Sí",1,0) -> #DIV/0! | BZ14: =+DATOS_[[#This Row],[SALARIO BASE Eq]]+DATOS_[[#This Row],[Tot COMPL.SAL Eq]] -> #DIV/0! | CA14: {=(SUMPRODUCT((RngTipo=$CA$7)*(rngAnualizable="Sí")*(rngNormalizable="Sí")*(DATOS_[[#This Row],[Conc.Sal.01]:[C.Extra.05]]))*(1/DATOS_[[#This Row],[% anualiz]])*(1/DATOS_[[#This Row],[% normaliz]]) +SUMPRODUCT((RngTipo=$CA$7)*(rngAnualizable="Sí")*(rngNormalizable="No")*(DATOS_[[#This Row],[Conc.Sal.01]:[C.Extra.05]]))*(1/DATOS_[[#This Row],[% anualiz]]) +SUMPRODUCT((RngTipo=$CA$7)*(rngAnualizable="No")*(rngNormalizable="Sí")*(DATOS_[[#This Row],[Conc.Sal.01]:[C.Extra.05]]))*(1/DATOS_[[#This Row],[% normaliz]]) +SUMPRODUCT((RngTipo=$CA$7)*(rngAnualizable="No")*(rngNormalizable="No")*(DATOS_[[#This Row],[Conc.Sal.01]:[C.Extra.05]]))) *IF(DATOS_[[#This Row],[Check Equiparado]]="Sí",1,0)} -> #DIV/0! | CB14: =+DATOS_[[#This Row],[TOTAL SALARIO Eq]]+DATOS_[[#This Row],[Tot Extrasalarial Eq]] -> #DIV/0! | CC14: =DATOS_[[#This Row],[S.BASE]] -> 0 | CD14: =+SUM(DATOS_[[#This Row],[Conc.Sal.01]:[Conc.Sal.30]]) -> 0 | CE14: =+DATOS_[[#This Row],[SALARIO BASE Ef]]+DATOS_[[#This Row],[Tot COMPL.SAL Ef]] -> 0 | CF14: =+SUM(DATOS_[[#This Row],[C.Extra.01]:[C.Extra.05]]) -> 0 | CG14: =+DATOS_[[#This Row],[TOTAL SALARIO Ef]]+DATOS_[[#This Row],[Tot Extrasalarial Ef]] -> 0 | CH14: =MIN(IF(DATOS_[[#This Row],[Fecha Fin Contrato]]="",$D$4,DATOS_[[#This Row],[Fecha Fin Contrato]]),$D$4)-MAX(DATOS_[[#This Row],[Fecha de Contratación]],$D$3)+1 -> 1 | CI14: =IF(COUNTIFS(DATOS_[id],DATOS_[[#This Row],[id]])>1,DATOS_[[#This Row],[id]],"") | CJ14: =(Inicio!$G$10-DATOS_[[#This Row],[Fecha Nacimiento]])/365.25 -> 0 | CK14: =(Inicio!$G$10-DATOS_[[#This Row],[Fecha de Antigüedad]])/365.25 -> 0 | CL14: =+VLOOKUP(DATOS_[[#This Row],[Clave de Contrato]],TblTiposContrato13[],3,0) -> #N/A | CM14: =+VLOOKUP(DATOS_[[#This Row],[Clave de Contrato]],TblTiposContrato13[],4,0) -> #N/A | CN14: =VLOOKUP(DATOS_[[#This Row],[Edad]],CONTRATOS!TblRngEdad,2,1) -> 20 o menos | CO14: =VLOOKUP(DATOS_[[#This Row],[Antigüedad]],TblRngAntg14[],2,1) -> 0 a 1 años
BN15: =+MAX($D$3,DATOS_[[#This Row],[Fecha Inicio Sit. Contract.]]) -> 0 | BO15: =+MIN($D$4,DATOS_[[#This Row],[Fecha Fin Sit. Contract.]]) -> 0 | BP15: =+DATOS_[[#This Row],[% de jornada]]*IF(DATOS_[[#This Row],[% jornada reducida]]="",1,DATOS_[[#This Row],[% jornada reducida]]) -> 0 | BQ15: =+(DATOS_[[#This Row],[F.fin.cal]]-DATOS_[[#This Row],[F.ini.cal]]+1)/($D$4-$D$3+1) -> 1 | BR15: =IF(OR(AND(DATOS_[[#This Row],[Fecha Fin Contrato]]<$D$3,DATOS_[[#This Row],[Fecha Fin Contrato]]<>""),DATOS_[[#This Row],[Fecha de Contratación]]>$D$4),"Fuera","Dentro") -> Dentro | BS15: {=IF(MAX(IF(DATOS_[id]=DATOS_[[#This Row],[id]],DATOS_[F.fin.cal]))=DATOS_[[#This Row],[F.fin.cal]],"Sí","NO")} -> Sí | BT15: =IF(AND(DATOS_[[#This Row],[% normaliz]]<>1,DATOS_[[#This Row],[% anualiz]]=1),"Sí","NO") -> Sí | BU15: =IF(AND(DATOS_[[#This Row],[% normaliz]]=1,DATOS_[[#This Row],[% anualiz]]<>1),"Sí","NO") -> NO | BV15: =IF(AND(DATOS_[[#This Row],[% normaliz]]<>1,DATOS_[[#This Row],[% anualiz]]<>1),"Sí","NO") -> NO | BW15: =+IF(DATOS_[[#This Row],[% normaliz]]*DATOS_[[#This Row],[% anualiz]]=1,"NO","Sí") -> Sí | BX15: =(DATOS_[[#This Row],[S.BASE]]*(1/DATOS_[[#This Row],[% normaliz]])*(1/DATOS_[[#This Row],[% anualiz]]))*IF(DATOS_[[#This Row],[Check Equiparado]]="Sí",1,0) -> #DIV/0! | BY15: =(SUMPRODUCT((RngTipo=$BY$7)*(rngAnualizable="Sí")*(rngNormalizable="Sí")*(DATOS_[[#This Row],[Conc.Sal.01]:[C.Extra.05]]))*(1/DATOS_[[#This Row],[% anualiz]])*(1/DATOS_[[#This Row],[% normaliz]]) +SUMPRODUCT((RngTipo=$BY$7)*(rngAnualizable="Sí")*(rngNormalizable="No")*(DATOS_[[#This Row],[Conc.Sal.01]:[C.Extra.05]]))*(1/DATOS_[[#This Row],[% anualiz]]) +SUMPRODUCT((RngTipo=$BY$7)*(rngAnualizable="No")*(rngNormalizable="Sí")*(DATOS_[[#This Row],[Conc.Sal.01]:[C.Extra.05]]))*(1/DATOS_[[#This Row],[% normaliz]]) +SUMPRODUCT((RngTipo=$BY$7)*(rngAnualizable="No")*(rngNormalizable="No")*(DATOS_[[#This Row],[Conc.Sal.01]:[C.Extra.05]]))) *IF(DATOS_[[#This Row],[Check Equiparado]]="Sí",1,0) -> #DIV/0! | BZ15: =+DATOS_[[#This Row],[SALARIO BASE Eq]]+DATOS_[[#This Row],[Tot COMPL.SAL Eq]] -> #DIV/0! | CA15: {=(SUMPRODUCT((RngTipo=$CA$7)*(rngAnualizable="Sí")*(rngNormalizable="Sí")*(DATOS_[[#This Row],[Conc.Sal.01]:[C.Extra.05]]))*(1/DATOS_[[#This Row],[% anualiz]])*(1/DATOS_[[#This Row],[% normaliz]]) +SUMPRODUCT((RngTipo=$CA$7)*(rngAnualizable="Sí")*(rngNormalizable="No")*(DATOS_[[#This Row],[Conc.Sal.01]:[C.Extra.05]]))*(1/DATOS_[[#This Row],[% anualiz]]) +SUMPRODUCT((RngTipo=$CA$7)*(rngAnualizable="No")*(rngNormalizable="Sí")*(DATOS_[[#This Row],[Conc.Sal.01]:[C.Extra.05]]))*(1/DATOS_[[#This Row],[% normaliz]]) +SUMPRODUCT((RngTipo=$CA$7)*(rngAnualizable="No")*(rngNormalizable="No")*(DATOS_[[#This Row],[Conc.Sal.01]:[C.Extra.05]]))) *IF(DATOS_[[#This Row],[Check Equiparado]]="Sí",1,0)} -> #DIV/0! | CB15: =+DATOS_[[#This Row],[TOTAL SALARIO Eq]]+DATOS_[[#This Row],[Tot Extrasalarial Eq]] -> #DIV/0! | CC15: =DATOS_[[#This Row],[S.BASE]] -> 0 | CD15: =+SUM(DATOS_[[#This Row],[Conc.Sal.01]:[Conc.Sal.30]]) -> 0 | CE15: =+DATOS_[[#This Row],[SALARIO BASE Ef]]+DATOS_[[#This Row],[Tot COMPL.SAL Ef]] -> 0 | CF15: =+SUM(DATOS_[[#This Row],[C.Extra.01]:[C.Extra.05]]) -> 0 | CG15: =+DATOS_[[#This Row],[TOTAL SALARIO Ef]]+DATOS_[[#This Row],[Tot Extrasalarial Ef]] -> 0 | CH15: =MIN(IF(DATOS_[[#This Row],[Fecha Fin Contrato]]="",$D$4,DATOS_[[#This Row],[Fecha Fin Contrato]]),$D$4)-MAX(DATOS_[[#This Row],[Fecha de Contratación]],$D$3)+1 -> 1 | CI15: =IF(COUNTIFS(DATOS_[id],DATOS_[[#This Row],[id]])>1,DATOS_[[#This Row],[id]],"") | CJ15: =(Inicio!$G$10-DATOS_[[#This Row],[Fecha Nacimiento]])/365.25 -> 0 | CK15: =(Inicio!$G$10-DATOS_[[#This Row],[Fecha de Antigüedad]])/365.25 -> 0 | CL15: =+VLOOKUP(DATOS_[[#This Row],[Clave de Contrato]],TblTiposContrato13[],3,0) -> #N/A | CM15: =+VLOOKUP(DATOS_[[#This Row],[Clave de Contrato]],TblTiposContrato13[],4,0) -> #N/A | CN15: =VLOOKUP(DATOS_[[#This Row],[Edad]],CONTRATOS!TblRngEdad,2,1) -> 20 o menos | CO15: =VLOOKUP(DATOS_[[#This Row],[Antigüedad]],TblRngAntg14[],2,1) -> 0 a 1 años
BN16: =+MAX($D$3,DATOS_[[#This Row],[Fecha Inicio Sit. Contract.]]) -> 0 | BO16: =+MIN($D$4,DATOS_[[#This Row],[Fecha Fin Sit. Contract.]]) -> 0 | BP16: =+DATOS_[[#This Row],[% de jornada]]*IF(DATOS_[[#This Row],[% jornada reducida]]="",1,DATOS_[[#This Row],[% jornada reducida]]) -> 0 | BQ16: =+(DATOS_[[#This Row],[F.fin.cal]]-DATOS_[[#This Row],[F.ini.cal]]+1)/($D$4-$D$3+1) -> 1 | BR16: =IF(OR(AND(DATOS_[[#This Row],[Fecha Fin Contrato]]<$D$3,DATOS_[[#This Row],[Fecha Fin Contrato]]<>""),DATOS_[[#This Row],[Fecha de Contratación]]>$D$4),"Fuera","Dentro") -> Dentro | BS16: {=IF(MAX(IF(DATOS_[id]=DATOS_[[#This Row],[id]],DATOS_[F.fin.cal]))=DATOS_[[#This Row],[F.fin.cal]],"Sí","NO")} -> Sí | BT16: =IF(AND(DATOS_[[#This Row],[% normaliz]]<>1,DATOS_[[#This Row],[% anualiz]]=1),"Sí","NO") -> Sí | BU16: =IF(AND(DATOS_[[#This Row],[% normaliz]]=1,DATOS_[[#This Row],[% anualiz]]<>1),"Sí","NO") -> NO | BV16: =IF(AND(DATOS_[[#This Row],[% normaliz]]<>1,DATOS_[[#This Row],[% anualiz]]<>1),"Sí","NO") -> NO | BW16: =+IF(DATOS_[[#This Row],[% normaliz]]*DATOS_[[#This Row],[% anualiz]]=1,"NO","Sí") -> Sí | BX16: =(DATOS_[[#This Row],[S.BASE]]*(1/DATOS_[[#This Row],[% normaliz]])*(1/DATOS_[[#This Row],[% anualiz]]))*IF(DATOS_[[#This Row],[Check Equiparado]]="Sí",1,0) -> #DIV/0! | BY16: =(SUMPRODUCT((RngTipo=$BY$7)*(rngAnualizable="Sí")*(rngNormalizable="Sí")*(DATOS_[[#This Row],[Conc.Sal.01]:[C.Extra.05]]))*(1/DATOS_[[#This Row],[% anualiz]])*(1/DATOS_[[#This Row],[% normaliz]]) +SUMPRODUCT((RngTipo=$BY$7)*(rngAnualizable="Sí")*(rngNormalizable="No")*(DATOS_[[#This Row],[Conc.Sal.01]:[C.Extra.05]]))*(1/DATOS_[[#This Row],[% anualiz]]) +SUMPRODUCT((RngTipo=$BY$7)*(rngAnualizable="No")*(rngNormalizable="Sí")*(DATOS_[[#This Row],[Conc.Sal.01]:[C.Extra.05]]))*(1/DATOS_[[#This Row],[% normaliz]]) +SUMPRODUCT((RngTipo=$BY$7)*(rngAnualizable="No")*(rngNormalizable="No")*(DATOS_[[#This Row],[Conc.Sal.01]:[C.Extra.05]]))) *IF(DATOS_[[#This Row],[Check Equiparado]]="Sí",1,0) -> #DIV/0! | BZ16: =+DATOS_[[#This Row],[SALARIO BASE Eq]]+DATOS_[[#This Row],[Tot COMPL.SAL Eq]] -> #DIV/0! | CA16: {=(SUMPRODUCT((RngTipo=$CA$7)*(rngAnualizable="Sí")*(rngNormalizable="Sí")*(DATOS_[[#This Row],[Conc.Sal.01]:[C.Extra.05]]))*(1/DATOS_[[#This Row],[% anualiz]])*(1/DATOS_[[#This Row],[% normaliz]]) +SUMPRODUCT((RngTipo=$CA$7)*(rngAnualizable="Sí")*(rngNormalizable="No")*(DATOS_[[#This Row],[Conc.Sal.01]:[C.Extra.05]]))*(1/DATOS_[[#This Row],[% anualiz]]) +SUMPRODUCT((RngTipo=$CA$7)*(rngAnualizable="No")*(rngNormalizable="Sí")*(DATOS_[[#This Row],[Conc.Sal.01]:[C.Extra.05]]))*(1/DATOS_[[#This Row],[% normaliz]]) +SUMPRODUCT((RngTipo=$CA$7)*(rngAnualizable="No")*(rngNormalizable="No")*(DATOS_[[#This Row],[Conc.Sal.01]:[C.Extra.05]]))) *IF(DATOS_[[#This Row],[Check Equiparado]]="Sí",1,0)} -> #DIV/0! | CB16: =+DATOS_[[#This Row],[TOTAL SALARIO Eq]]+DATOS_[[#This Row],[Tot Extrasalarial Eq]] -> #DIV/0! | CC16: =DATOS_[[#This Row],[S.BASE]] -> 0 | CD16: =+SUM(DATOS_[[#This Row],[Conc.Sal.01]:[Conc.Sal.30]]) -> 0 | CE16: =+DATOS_[[#This Row],[SALARIO BASE Ef]]+DATOS_[[#This Row],[Tot COMPL.SAL Ef]] -> 0 | CF16: =+SUM(DATOS_[[#This Row],[C.Extra.01]:[C.Extra.05]]) -> 0 | CG16: =+DATOS_[[#This Row],[TOTAL SALARIO Ef]]+DATOS_[[#This Row],[Tot Extrasalarial Ef]] -> 0 | CH16: =MIN(IF(DATOS_[[#This Row],[Fecha Fin Contrato]]="",$D$4,DATOS_[[#This Row],[Fecha Fin Contrato]]),$D$4)-MAX(DATOS_[[#This Row],[Fecha de Contratación]],$D$3)+1 -> 1 | CI16: =IF(COUNTIFS(DATOS_[id],DATOS_[[#This Row],[id]])>1,DATOS_[[#This Row],[id]],"") | CJ16: =(Inicio!$G$10-DATOS_[[#This Row],[Fecha Nacimiento]])/365.25 -> 0 | CK16: =(Inicio!$G$10-DATOS_[[#This Row],[Fecha de Antigüedad]])/365.25 -> 0 | CL16: =+VLOOKUP(DATOS_[[#This Row],[Clave de Contrato]],TblTiposContrato13[],3,0) -> #N/A | CM16: =+VLOOKUP(DATOS_[[#This Row],[Clave de Contrato]],TblTiposContrato13[],4,0) -> #N/A | CN16: =VLOOKUP(DATOS_[[#This Row],[Edad]],CONTRATOS!TblRngEdad,2,1) -> 20 o menos | CO16: =VLOOKUP(DATOS_[[#This Row],[Antigüedad]],TblRngAntg14[],2,1) -> 0 a 1 años
BN17: =+MAX($D$3,DATOS_[[#This Row],[Fecha Inicio Sit. Contract.]]) -> 0 | BO17: =+MIN($D$4,DATOS_[[#This Row],[Fecha Fin Sit. Contract.]]) -> 0 | BP17: =+DATOS_[[#This Row],[% de jornada]]*IF(DATOS_[[#This Row],[% jornada reducida]]="",1,DATOS_[[#This Row],[% jornada reducida]]) -> 0 | BQ17: =+(DATOS_[[#This Row],[F.fin.cal]]-DATOS_[[#This Row],[F.ini.cal]]+1)/($D$4-$D$3+1) -> 1 | BR17: =IF(OR(AND(DATOS_[[#This Row],[Fecha Fin Contrato]]<$D$3,DATOS_[[#This Row],[Fecha Fin Contrato]]<>""),DATOS_[[#This Row],[Fecha de Contratación]]>$D$4),"Fuera","Dentro") -> Dentro | BS17: {=IF(MAX(IF(DATOS_[id]=DATOS_[[#This Row],[id]],DATOS_[F.fin.cal]))=DATOS_[[#This Row],[F.fin.cal]],"Sí","NO")} -> Sí | BT17: =IF(AND(DATOS_[[#This Row],[% normaliz]]<>1,DATOS_[[#This Row],[% anualiz]]=1),"Sí","NO") -> Sí | BU17: =IF(AND(DATOS_[[#This Row],[% normaliz]]=1,DATOS_[[#This Row],[% anualiz]]<>1),"Sí","NO") -> NO | BV17: =IF(AND(DATOS_[[#This Row],[% normaliz]]<>1,DATOS_[[#This Row],[% anualiz]]<>1),"Sí","NO") -> NO | BW17: =+IF(DATOS_[[#This Row],[% normaliz]]*DATOS_[[#This Row],[% anualiz]]=1,"NO","Sí") -> Sí | BX17: =(DATOS_[[#This Row],[S.BASE]]*(1/DATOS_[[#This Row],[% normaliz]])*(1/DATOS_[[#This Row],[% anualiz]]))*IF(DATOS_[[#This Row],[Check Equiparado]]="Sí",1,0) -> #DIV/0! | BY17: =(SUMPRODUCT((RngTipo=$BY$7)*(rngAnualizable="Sí")*(rngNormalizable="Sí")*(DATOS_[[#This Row],[Conc.Sal.01]:[C.Extra.05]]))*(1/DATOS_[[#This Row],[% anualiz]])*(1/DATOS_[[#This Row],[% normaliz]]) +SUMPRODUCT((RngTipo=$BY$7)*(rngAnualizable="Sí")*(rngNormalizable="No")*(DATOS_[[#This Row],[Conc.Sal.01]:[C.Extra.05]]))*(1/DATOS_[[#This Row],[% anualiz]]) +SUMPRODUCT((RngTipo=$BY$7)*(rngAnualizable="No")*(rngNormalizable="Sí")*(DATOS_[[#This Row],[Conc.Sal.01]:[C.Extra.05]]))*(1/DATOS_[[#This Row],[% normaliz]]) +SUMPRODUCT((RngTipo=$BY$7)*(rngAnualizable="No")*(rngNormalizable="No")*(DATOS_[[#This Row],[Conc.Sal.01]:[C.Extra.05]]))) *IF(DATOS_[[#This Row],[Check Equiparado]]="Sí",1,0) -> #DIV/0! | BZ17: =+DATOS_[[#This Row],[SALARIO BASE Eq]]+DATOS_[[#This Row],[Tot COMPL.SAL Eq]] -> #DIV/0! | CA17: {=(SUMPRODUCT((RngTipo=$CA$7)*(rngAnualizable="Sí")*(rngNormalizable="Sí")*(DATOS_[[#This Row],[Conc.Sal.01]:[C.Extra.05]]))*(1/DATOS_[[#This Row],[% anualiz]])*(1/DATOS_[[#This Row],[% normaliz]]) +SUMPRODUCT((RngTipo=$CA$7)*(rngAnualizable="Sí")*(rngNormalizable="No")*(DATOS_[[#This Row],[Conc.Sal.01]:[C.Extra.05]]))*(1/DATOS_[[#This Row],[% anualiz]]) +SUMPRODUCT((RngTipo=$CA$7)*(rngAnualizable="No")*(rngNormalizable="Sí")*(DATOS_[[#This Row],[Conc.Sal.01]:[C.Extra.05]]))*(1/DATOS_[[#This Row],[% normaliz]]) +SUMPRODUCT((RngTipo=$CA$7)*(rngAnualizable="No")*(rngNormalizable="No")*(DATOS_[[#This Row],[Conc.Sal.01]:[C.Extra.05]]))) *IF(DATOS_[[#This Row],[Check Equiparado]]="Sí",1,0)} -> #DIV/0! | CB17: =+DATOS_[[#This Row],[TOTAL SALARIO Eq]]+DATOS_[[#This Row],[Tot Extrasalarial Eq]] -> #DIV/0! | CC17: =DATOS_[[#This Row],[S.BASE]] -> 0 | CD17: =+SUM(DATOS_[[#This Row],[Conc.Sal.01]:[Conc.Sal.30]]) -> 0 | CE17: =+DATOS_[[#This Row],[SALARIO BASE Ef]]+DATOS_[[#This Row],[Tot COMPL.SAL Ef]] -> 0 | CF17: =+SUM(DATOS_[[#This Row],[C.Extra.01]:[C.Extra.05]]) -> 0 | CG17: =+DATOS_[[#This Row],[TOTAL SALARIO Ef]]+DATOS_[[#This Row],[Tot Extrasalarial Ef]] -> 0 | CH17: =MIN(IF(DATOS_[[#This Row],[Fecha Fin Contrato]]="",$D$4,DATOS_[[#This Row],[Fecha Fin Contrato]]),$D$4)-MAX(DATOS_[[#This Row],[Fecha de Contratación]],$D$3)+1 -> 1 | CI17: =IF(COUNTIFS(DATOS_[id],DATOS_[[#This Row],[id]])>1,DATOS_[[#This Row],[id]],"") | CJ17: =(Inicio!$G$10-DATOS_[[#This Row],[Fecha Nacimiento]])/365.25 -> 0 | CK17: =(Inicio!$G$10-DATOS_[[#This Row],[Fecha de Antigüedad]])/365.25 -> 0 | CL17: =+VLOOKUP(DATOS_[[#This Row],[Clave de Contrato]],TblTiposContrato13[],3,0) -> #N/A | CM17: =+VLOOKUP(DATOS_[[#This Row],[Clave de Contrato]],TblTiposContrato13[],4,0) -> #N/A | CN17: =VLOOKUP(DATOS_[[#This Row],[Edad]],CONTRATOS!TblRngEdad,2,1) -> 20 o menos | CO17: =VLOOKUP(DATOS_[[#This Row],[Antigüedad]],TblRngAntg14[],2,1) -> 0 a 1 años
BN18: =+MAX($D$3,DATOS_[[#This Row],[Fecha Inicio Sit. Contract.]]) -> 0 | BO18: =+MIN($D$4,DATOS_[[#This Row],[Fecha Fin Sit. Contract.]]) -> 0 | BP18: =+DATOS_[[#This Row],[% de jornada]]*IF(DATOS_[[#This Row],[% jornada reducida]]="",1,DATOS_[[#This Row],[% jornada reducida]]) -> 0 | BQ18: =+(DATOS_[[#This Row],[F.fin.cal]]-DATOS_[[#This Row],[F.ini.cal]]+1)/($D$4-$D$3+1) -> 1 | BR18: =IF(OR(AND(DATOS_[[#This Row],[Fecha Fin Contrato]]<$D$3,DATOS_[[#This Row],[Fecha Fin Contrato]]<>""),DATOS_[[#This Row],[Fecha de Contratación]]>$D$4),"Fuera","Dentro") -> Dentro | BS18: {=IF(MAX(IF(DATOS_[id]=DATOS_[[#This Row],[id]],DATOS_[F.fin.cal]))=DATOS_[[#This Row],[F.fin.cal]],"Sí","NO")} -> Sí | BT18: =IF(AND(DATOS_[[#This Row],[% normaliz]]<>1,DATOS_[[#This Row],[% anualiz]]=1),"Sí","NO") -> Sí | BU18: =IF(AND(DATOS_[[#This Row],[% normaliz]]=1,DATOS_[[#This Row],[% anualiz]]<>1),"Sí","NO") -> NO | BV18: =IF(AND(DATOS_[[#This Row],[% normaliz]]<>1,DATOS_[[#This Row],[% anualiz]]<>1),"Sí","NO") -> NO | BW18: =+IF(DATOS_[[#This Row],[% normaliz]]*DATOS_[[#This Row],[% anualiz]]=1,"NO","Sí") -> Sí | BX18: =(DATOS_[[#This Row],[S.BASE]]*(1/DATOS_[[#This Row],[% normaliz]])*(1/DATOS_[[#This Row],[% anualiz]]))*IF(DATOS_[[#This Row],[Check Equiparado]]="Sí",1,0) -> #DIV/0! | BY18: =(SUMPRODUCT((RngTipo=$BY$7)*(rngAnualizable="Sí")*(rngNormalizable="Sí")*(DATOS_[[#This Row],[Conc.Sal.01]:[C.Extra.05]]))*(1/DATOS_[[#This Row],[% anualiz]])*(1/DATOS_[[#This Row],[% normaliz]]) +SUMPRODUCT((RngTipo=$BY$7)*(rngAnualizable="Sí")*(rngNormalizable="No")*(DATOS_[[#This Row],[Conc.Sal.01]:[C.Extra.05]]))*(1/DATOS_[[#This Row],[% anualiz]]) +SUMPRODUCT((RngTipo=$BY$7)*(rngAnualizable="No")*(rngNormalizable="Sí")*(DATOS_[[#This Row],[Conc.Sal.01]:[C.Extra.05]]))*(1/DATOS_[[#This Row],[% normaliz]]) +SUMPRODUCT((RngTipo=$BY$7)*(rngAnualizable="No")*(rngNormalizable="No")*(DATOS_[[#This Row],[Conc.Sal.01]:[C.Extra.05]]))) *IF(DATOS_[[#This Row],[Check Equiparado]]="Sí",1,0) -> #DIV/0! | BZ18: =+DATOS_[[#This Row],[SALARIO BASE Eq]]+DATOS_[[#This Row],[Tot COMPL.SAL Eq]] -> #DIV/0! | CA18: {=(SUMPRODUCT((RngTipo=$CA$7)*(rngAnualizable="Sí")*(rngNormalizable="Sí")*(DATOS_[[#This Row],[Conc.Sal.01]:[C.Extra.05]]))*(1/DATOS_[[#This Row],[% anualiz]])*(1/DATOS_[[#This Row],[% normaliz]]) +SUMPRODUCT((RngTipo=$CA$7)*(rngAnualizable="Sí")*(rngNormalizable="No")*(DATOS_[[#This Row],[Conc.Sal.01]:[C.Extra.05]]))*(1/DATOS_[[#This Row],[% anualiz]]) +SUMPRODUCT((RngTipo=$CA$7)*(rngAnualizable="No")*(rngNormalizable="Sí")*(DATOS_[[#This Row],[Conc.Sal.01]:[C.Extra.05]]))*(1/DATOS_[[#This Row],[% normaliz]]) +SUMPRODUCT((RngTipo=$CA$7)*(rngAnualizable="No")*(rngNormalizable="No")*(DATOS_[[#This Row],[Conc.Sal.01]:[C.Extra.05]]))) *IF(DATOS_[[#This Row],[Check Equiparado]]="Sí",1,0)} -> #DIV/0! | CB18: =+DATOS_[[#This Row],[TOTAL SALARIO Eq]]+DATOS_[[#This Row],[Tot Extrasalarial Eq]] -> #DIV/0! | CC18: =DATOS_[[#This Row],[S.BASE]] -> 0 | CD18: =+SUM(DATOS_[[#This Row],[Conc.Sal.01]:[Conc.Sal.30]]) -> 0 | CE18: =+DATOS_[[#This Row],[SALARIO BASE Ef]]+DATOS_[[#This Row],[Tot COMPL.SAL Ef]] -> 0 | CF18: =+SUM(DATOS_[[#This Row],[C.Extra.01]:[C.Extra.05]]) -> 0 | CG18: =+DATOS_[[#This Row],[TOTAL SALARIO Ef]]+DATOS_[[#This Row],[Tot Extrasalarial Ef]] -> 0 | CH18: =MIN(IF(DATOS_[[#This Row],[Fecha Fin Contrato]]="",$D$4,DATOS_[[#This Row],[Fecha Fin Contrato]]),$D$4)-MAX(DATOS_[[#This Row],[Fecha de Contratación]],$D$3)+1 -> 1 | CI18: =IF(COUNTIFS(DATOS_[id],DATOS_[[#This Row],[id]])>1,DATOS_[[#This Row],[id]],"") | CJ18: =(Inicio!$G$10-DATOS_[[#This Row],[Fecha Nacimiento]])/365.25 -> 0 | CK18: =(Inicio!$G$10-DATOS_[[#This Row],[Fecha de Antigüedad]])/365.25 -> 0 | CL18: =+VLOOKUP(DATOS_[[#This Row],[Clave de Contrato]],TblTiposContrato13[],3,0) -> #N/A | CM18: =+VLOOKUP(DATOS_[[#This Row],[Clave de Contrato]],TblTiposContrato13[],4,0) -> #N/A | CN18: =VLOOKUP(DATOS_[[#This Row],[Edad]],CONTRATOS!TblRngEdad,2,1) -> 20 o menos | CO18: =VLOOKUP(DATOS_[[#This Row],[Antigüedad]],TblRngAntg14[],2,1) -> 0 a 1 años
